Workbook

Sheet Sheet1
A1: Grasmere Farm Manual
A2: Kitchen KPI Weekly Summary Sheet W/C
B3: COST PRiCE | C3: WEEKLY PREPPED TOTAL | D3: POINT VALUE | E3: POINTS TOTAL | F3: STOCK VALUE TOTAL
A4: MEAT PIES SMALL
A5: Steak | B5: ='Steak Pie v2'!D66 -> 1.423461 | D5: 1
A6: Steak & Ale | B6: ='Steak & Ale Pie'!D56 -> #NAME? | D6: 1
A7: Steak & Kidney | B7: ='Steak & Kidney Pie'!D52 -> 1.5362969 | D7: 1
A8: Steak & Stilton | B8: ='Steak & Stilton Pie'!D53 -> 1.6345876
A9: Chicken & Ham | B9: ='C&H Pie'!D49 -> 1.2106156 | D9: 1
A10: Chicken & Chorizo | B10: ='C&C Pie'!D62 -> 1.2049576 | D10: 1
A11: Chicken & Bacon with Stilton | B11: ='C&S Pie'!D52 -> 1.2636383 | D11: 1
A12: Pulled Pork, Cider & Mustard | B12: ='Pulled Pork Pie'!D50 -> 1.3805483 | D12: 1
A13: Ham Hock, Cider & Tarragon | B13: ='Ham Hock Pie'!D52 -> 1.2270388 | D13: 1
A14: TOTAL
A16: MEAT PIES MEDIUM
A17: Steak | B17: ='Steak Pie v2'!I66 -> 2.6404446 | D17: 2
A18: Steak & Ale | B18: ='Steak & Ale Pie'!I56 -> #REF! | D18: 2
A19: Steak & Kidney | B19: ='Steak & Kidney Pie'!I52 -> 2.5079359 | D19: 2
A20: Steak & Stilton | B20: ='Steak & Stilton Pie'!I53 -> 2.7026668
A21: Chicken & Ham | B21: ='C&H Pie'!I50 -> 2.4726485 | D21: 2
A22: Chicken & Chorizo | B22: ='C&C Pie'!I62 -> 1.8928079 | D22: 2
A23: Chicken & Bacon with Stilton | B23: ='C&S Pie'!I52 -> 2.0032005 | D23: 2
A24: Pulled Pork, Cider & Mustard | B24: ='Pulled Pork Pie'!I50 -> 2.2361144 | D24: 2
A25: Ham Hock, Cider & Tarragon | B25: ='Ham Hock Pie'!I52 -> 2.1971121 | D25: 2
A26: TOTAL
A28: MEAT PIES LARGE
A29: Steak | B29: ='Steak Pie v2'!N54 -> 5.3284461 | D29: 3
A30: Steak & Ale | B30: ='Steak & Ale Pie'!N40 -> 5.3580408 | D30: 3
A31: Steak & Kidney | B31: ='Steak & Kidney Pie'!N37 -> 5.0774503 | D31: 3
A32: Chicken & Ham | B32: ='Steak & Stilton Pie'!I65 -> 0 | D32: 3
A33: Chicken & Chorizo | B33: ='C&H Pie'!I62 -> 0 | D33: 3
A34: Chicken & Bacon with Stilton | B34: ='C&C Pie'!I74 -> 0 | D34: 3
A35: Pulled Pork, Cider & Mustard | B35: ='C&S Pie'!I64 -> 0 | D35: 3
A36: Ham Hock, Cider & Tarragon | B36: ='Pulled Pork Pie'!I62 -> 0 | D36: 3
A37: TOTAL | B37: ='Ham Hock Pie'!I64 -> 0
A39: PORK PIES
A40: 3lb | D40: 6
A41: 2lb | D41: 3
A42: Medium | D42: 1
A43: Small | D43: 1
...

Sheet Ingredient Cost
A1: Kitchen Ingredient Costs
A2: Change info in yellow boxes
H3: Labour | J3: 20 | K3: per hour
A4: INGREDIENT | D4: COST | E4: PER
A5: PASTRY
A6: Fat/Butter/Lard | D6: 2.06 | E6: kg
A7: Flour | D7: 0.62 | E7: kg
A8: Salt | D8: 0.54 | E8: kg
A9: Pukka Puffy Pastry | D9: 1.94 | E9: kg
A10: Pepper | D10: 11 | E10: kg
A11: Egg/Milk Wash | D11: 0.02 | E11: per egg wash | G11: 16 eggs | H11: 2.93 | I11: 0.11
A12: Milk | D12: 0.74 | E12: per kg | G12: 2 ltre milk | H12: 1.48
H13: 4.41
A14: OTHER
A15: Vegetable Oil | D15: 1.29 | E15: per kg
A16: Hard Boiled Eggs | D16: 0.27 | E16: each
A17: Crumb | D17: 1.26 | E17: kg
A18: Stilton | D18: 4.75 | E18: kg
A19: Lincolnshire Poacher | D19: 25.2 | E19: kg
A20: Chicken Sauce Mix | D20: 8.95 | E20: kg
A21: Steak & Kidney Sauce Mix | D21: 8.9 | E21: kg | F21: ?
A22: Tarigan | D22: 13 | E22: kg
A23: Powder Mustard | D23: 9.37 | E23: kg
A24: Grain Mustard | D24: 7.65 | E24: kg
A25: Mace | D25: 36.9 | E25: kg
A26: Barley | D26: 0.83 | E26: kg
A27: Rusk | D27: 1.18 | E27: kg | F27: 18 | G27: 20kg
A28: Cider | D28: 1.15 | E28: kg
A29: Ale | D29: 1.38 | E29: kg
A30: Brown Sugar | D30: 1.02 | E30: kg
A32: Red Onions | D32: 13.5 | E32: kg
A33: Brown Onions | E33: kg
A34: Red wine vinegar | D34: 5.27 | E34: kg
A35: Chilli Flakes | D35: 9.4 | E35: kg
A36: Spiced Fruit Chutney | D36: 7.01 | E36: kg
A37: Real Ale Chutney | D37: 7.43
A38: Cranberrys | D38: 4.08 | E38: kg
A39: Ox Runners | D39: 17.11 | E39: per bundle
A40: Pork Pie Seasoning
A41: Red wine | D41: 0.66
...

Sheet Sliced Ham
A1: Grasmere Farm Manual
A2: Product Page
A3: Sliced Ham
A6: HAM 1
A7: Input / Calculation | D7: Cost Per pack | E7: No | F7: Cost | G7: Total | N7: Butchery charge | P7: £25 each
A8: Raw start weight (kg) | B8: 8.002 | D8: Ham 180g pack | E8: 22 | F8: =B13*0.18 -> 1.4330855 | G8: =E8*F8 -> 31.52788 | N8: Kitchen
A9: Raw cost per kg (£) | B9: 3.94 | D9: Cook Bag | E9: 1 | F9: ='Ingredient Cost'!D106 -> 0.87 | G9: =E9*F9 -> 0.87
A10: Total raw cost (£) | B10: =B8*B9 -> 31.52788 | D10: Packaging | E10: =E8*E9 -> 22 | F10: ='Ingredient Cost'!D105 -> 0.07 | G10: =E10*F10 -> 1.54
A11: Cooked saleable weight (kg) | B11: 4.412 | D11: Label | E11: 22 | F11: ='Ingredient Cost'!D110 -> 0.01 | G11: =E11*F11 -> 0.22
A12: Cooked yield (%) | B12: =B11/B8 -> 0.55136216 | D12: Labour | E12: 54 | F12: 20 | G12: =F12/E12 -> 0.37037037
A13: Cooked cost per kg (£) | B13: =B10/(B11-B14) -> 7.9615859
A14: Waste (kg) | B14: 0.452
A15: Waste % of cooked weight | B15: =B14/B11 -> 0.10244787 | D15: Cost per pack | G15: =SUM(G8:G12)/22 -> 1.5694659
A17: HAM 2
A18: Input / Calculation | D18: Cost Per pack | E18: No | F18: Cost | G18: Total
A19: Raw start weight (kg) | B19: 9.556 | D19: Ham 180g pack | E19: 25 | F19: =B24*0.18 -> 1.5060256 | G19: =E19*F19 -> 37.65064
A20: Raw cost per kg (£) | B20: 3.94 | D20: Cook Bag | E20: 1 | F20: =F9 -> 0.87 | G20: =E20*F20 -> 0.87
A21: Total raw cost (£) | B21: =B19*B20 -> 37.65064 | D21: Packaging | E21: =E19*E20 -> 25 | F21: =F10 -> 0.07 | G21: =E21*F21 -> 1.75
A22: Cooked saleable weight (kg) | B22: 4.944 | D22: Label | E22: 25 | F22: =F11 -> 0.01 | G22: =E22*F22 -> 0.25
A23: Cooked yield (%) | B23: =B22/B19 -> 0.51737129 | D23: Labour | E23: 54 | F23: 20 | G23: =F23/E23 -> 0.37037037
A24: Cooked cost per kg (£) | B24: =B21/(B22-B25) -> 8.3668089
A25: Waste (kg) | B25: 0.444
A26: Waste % of cooked weight | B26: =B25/B22 -> 0.089805825 | D26: Cost per pack | G26: =SUM(G19:G23)/25 -> 1.6356404
A29: HAM 3
A30: Input / Calculation | D30: Cost Per pack | E30: No | F30: Cost | G30: Total
A31: Raw start weight (kg) | B31: 9.678 | D31: Ham 180g pack | E31: 22 | F31: =B36*0.18 -> 1.7332418 | G31: =E31*F31 -> 38.13132
A32: Raw cost per kg (£) | B32: 3.94 | D32: Cook Bag | E32: 1 | F32: =F9 -> 0.87 | G32: =E32*F32 -> 0.87
A33: Total raw cost (£) | B33: =B31*B32 -> 38.13132 | D33: Packaging | E33: =E31*E32 -> 22 | F33: =F10 -> 0.07 | G33: =E33*F33 -> 1.54
A34: Cooked saleable weight (kg) | B34: 4.91 | D34: Label | E34: 22 | F34: =F11 -> 0.01 | G34: =E34*F34 -> 0.22
A35: Cooked yield (%) | B35: =B34/B31 -> 0.50733623 | D35: Labour | E35: 54 | F35: 20 | G35: =F35/E35 -> 0.37037037
A36: Cooked cost per kg (£) | B36: =B33/(B34-B37) -> 9.6291212
A37: Waste (kg) | B37: 0.95
A38: Waste % of cooked weight | B38: =B37/B34 -> 0.19348269 | D38: Cost per pack | G38: =SUM(G31:G35)/22 -> 1.8696223
A40: HAM 4
A41: Input / Calculation | D41: Cost Per pack | E41: No | F41: Cost | G41: Total
A42: Raw start weight (kg) | B42: 11.066 | D42: Ham 180g pack | E42: 29 | F42: =B47*0.18 -> 1.5092322 | G42: =E42*F42 -> 43.767732
A43: Raw cost per kg (£) | B43: 3.94 | D43: Cook Bag | E43: 1 | F43: =F9 -> 0.87 | G43: =E43*F43 -> 0.87
A44: Total raw cost (£) | B44: =B42*B43 -> 43.60004 | D44: Packaging | E44: =E42*E43 -> 29 | F44: =F10 -> 0.07 | G44: =E44*F44 -> 2.03
A45: Cooked saleable weight (kg) | B45: 5.724 | D45: Label | E45: 29 | F45: =F11 -> 0.01 | G45: =E45*F45 -> 0.29
A46: Cooked yield (%) | B46: =B45/B42 -> 0.51726008 | D46: Labour | E46: 54 | F46: 20 | G46: =F46/E46 -> 0.37037037
...

Sheet Haslet
A1: Grasmere Farm Manual
A2: Product Page
A3: Haslets
A4: INGREDIENTS | B4: . All allergens in BOLD.
A16: Product | B16: Haslet 1lb | F16: Product | G16: Haslet packaged | K16: Product | L16: Haslet boxed
B17: Weight | C17: Cost | D17: Total | G17: Weight | H17: Cost | I17: Total | L17: Weight | M17: Cost | N17: Total
A18: Pork Meat | B18: 0.454 | C18: ='Ingredient Cost'!D56 -> 61.36 | D18: =B18*C18 -> 27.85744 | F18: Haslet | G18: 1 | H18: =D26 -> 28.17494 | I18: =G18*H18 -> 28.17494 | K18: Haslet | L18: 6 | M18: =I26 -> 28.40994 | N18: =L18*M18 -> 170.45964
A19: Vale Fat | B19: 0.03 | C19: ='Ingredient Cost'!D78 -> 2.25 | D19: =B19*C19 -> 0.0675 | F19: Packaging | G19: 1 | H19: ='Ingredient Cost'!D88 -> 0.09 | I19: =G19*H19 -> 0.09 | K19: Case | L19: 1 | M19: ='Ingredient Cost'!D108 -> 0.2 | N19: =L19*M19 -> 0.2
F20: Label/etc | G20: 1 | H20: 0.02 | I20: =H20/G20 -> 0.02 | K20: Label | M20: 0.01 | N20: =M20 -> 0.01
F21: Labour | G21: 120 | H21: 15 | I21: =H21/G21 -> 0.125 | K21: Labour | L21: 20 | M21: 15 | N21: =M21/L21 -> 0.75
A22: Labour | B22: 60 | C22: 15 | D22: =C22/B22 -> 0.25
A26: COST | D26: =SUM(D18:D22) -> 28.17494 | F26: COST | I26: =SUM(I18:I22) -> 28.40994 | K26: COST | N26: =SUM(N18:N22) -> 171.41964
K27: PER EACH | N27: =N26/6 -> 28.56994
A30: Product | B30: Haslet 6lb | F30: Product | G30: Haslet 6lb-sliced Case
B31: Weight | C31: Cost | D31: Total | G31: Weight | H31: Cost | I31: Total
A32: Pork Meat | B32: 2.724 | C32: ='Ingredient Cost'!D56 -> 61.36 | D32: =B32*C32 -> 167.14464 | F32: Haslet | G32: 1.56 | H32: =D40 -> 61.561385 | I32: =G32*H32 -> 96.03576
A33: Paper | B33: 1 | C33: ='Ingredient Cost'!D86 -> 0.12 | D33: =B33*C33 -> 0.12 | F33: Vac Bag | G33: 12 | H33: ='Ingredient Cost'!D105 -> 0.07 | I33: =G33*H33 -> 0.84
F34: Label | G34: 12 | H34: 0.01 | I34: =G34*H34 -> 0.12
A35: Labour | B35: 35 | C35: 15 | D35: =C35/B35 -> 0.42857143 | F35: Labour | G35: 90 | H35: 15 | I35: =H35/G35 -> 0.16666667
F36: Case | G36: 1 | H36: ='Ingredient Cost'!D108 -> 0.2 | I36: =H36/G36 -> 0.2
F37: End Label | G37: 1 | H37: 0.01 | I37: =H37/G37 -> 0.01
A39: COST | D39: =SUM(D32:D35) -> 167.69321 | F39: COST PER CASE | I39: =SUM(I32:I35) -> 97.162427
A40: PER KG | D40: =D39/B32 -> 61.561385 | F40: PER KG | I40: =I39/G32 -> 62.283607

Sheet Meatballs
A1: Grasmere Farm Manual
A2: Costing
A4: Product | F4: Product | G4: Meatballs
B5: Weight | C5: Cost | D5: Total | G5: Weight | H5: Cost | I5: Total
A6: Start weight (before hung if dry aged) | B6: 0.34 | F6: Meatball Pack | G6: 6 | H6: =D14 -> 0 | I6: =G6*H6 -> 0
A7: (Start weight after hanging if dry aged) | B7: 1 | F7: Case | G7: 1 | H7: ='Ingredient Cost'!D108 -> 0.2 | I7: =G7*H7 -> 0.2
A8: Product | B8: 1 | F8: Label | G8: 1 | H8: 0.01 | I8: =H8/G8 -> 0.01
A9: Trim | B9: 120 | F9: Labour | G9: 20 | H9: 15 | I9: =H9/G9 -> 0.75
A10: Waste
A14: COST PER PACK | D14: =SUM(D6:D10) -> 0 | F14: COST | I14: =SUM(I6:I10) -> 0.96

Sheet Black Pudding
A1: Grasmere Farm Manual
A2: Product Page
A3: Black Pudding
A4: INGREDIENTS | B4: . All allergens in BOLD.
A16: Product | B16: Black Pudding | F16: Black Pudding
B17: Weight | C17: Cost | D17: Total | G17: Weight | H17: Cost | I17: Total
A18: Pearl Barley | B18: 11 | C18: ='Ingredient Cost'!D26 -> 0.83 | D18: =B18*C18 -> 9.13 | F18: Black Pudding | G18: 0.25 | H18: =D26 -> 1.1688646 | I18: =G18*H18 -> 0.29221616
A19: Back Fat | B19: 11 | C19: ='Ingredient Cost'!D72 -> 1.7 | D19: =B19*C19 -> 18.7 | F19: Packaging | G19: 1 | H19: 0.1 | I19: =G19*H19 -> 0.1
A20: Cooked Onion | B20: 5 | C20: ='Ingredient Cost'!D33 -> 0 | D20: =B20*C20 -> 0 | F20: Labour | G20: 180 | H20: 15 | I20: =H20/G20 -> 0.083333333
A21: Black Pudding Mix | B21: 10.8 | C21: 2.38 | D21: =B21*C21 -> 25.704
A22: Water | B22: 8 | C22: 0 | D22: =B22*C22 -> 0
A23: Skin | B23: ?
B24: =SUM(B18:B22) -> 45.8 | D24: =SUM(D18:D22) -> 53.534
A26: COST | D26: =SUM(D24/B24) -> 1.1688646 | F26: COST | I26: =SUM(I18:I24) -> 0.47554949

Sheet Faggots
A1: Grasmere Farm Manual
A2: Product Page
A3: Faggots
A4: INGREDIENTS | B4: . All allergens in BOLD.
A16: Product | B16: Faggot Meat Mix | F16: Product | G16: Faggot Mix | K16: Product | L16: Faggot (4 per pack)
B17: Weight | C17: Cost | D17: Total | G17: Weight | H17: Cost | I17: Total | L17: Weight | M17: Cost | N17: Total
A18: Pork Meat | B18: 3 | C18: ='Ingredient Cost'!D56 -> 61.36 | D18: =B18*C18 -> 184.08 | F18: Faggot Mix | G18: 10 | I18: =G18*H18 -> 0 | K18: Faggot | L18: 0.4 | M18: =I26 -> 0.048 | N18: =L18*M18 -> 0.0192
A19: Kidney | B19: 1 | C19: 2 | D19: =B19*C19 -> 2 | F19: OXO Cube | G19: 0.024 | H19: 2 | I19: =G19*H19 -> 0.048 | K19: Vail | L19: 0.07 | M19: ='Ingredient Cost'!I88 -> 0 | N19: =L19*M19 -> 0
A20: Heart | B20: 1 | C20: 2 | D20: =B20*C20 -> 2 | F20: Water | G20: 1 | H20: 0 | I20: =G20*H20 -> 0 | K20: Packaging | L20: 1 | M20: 0.2 | N20: =M20/L20 -> 0.2
A21: Liver | B21: 1.5 | C21: 2 | D21: =B21*C21 -> 3 | F21: Rusk | G21: 2 | H21: ='Ingredient Cost'!I26 -> 0 | I21: =G21*H21 -> 0 | K21: Labour | L21: 29 | M21: 15 | N21: =M21/L21 -> 0.51724138
A22: Garlic | B22: 0.1 | D22: =B22*C22 -> 0
A23: Onion | B23: 2 | C23: ='Ingredient Cost'!D33 -> 0 | D23: =B23*C23 -> 0
A26: COST | D26: =SUM(D18:D22) -> 191.08 | F26: COST | I26: =SUM(I18:I22) -> 0.048 | K26: COST | N26: =SUM(N18:N22) -> 0.73644138
A30: Product | B30: Haslet 6lb
B31: Weight | C31: Cost | D31: Total
A32: Pork Meat | B32: 2.724 | C32: ='Ingredient Cost'!D56 -> 61.36 | D32: =B32*C32 -> 167.14464
A33: Paper | B33: 1 | C33: ='Ingredient Cost'!D86 -> 0.12 | D33: =B33*C33 -> 0.12
A35: Labour | B35: 35 | C35: 15 | D35: =C35/B35 -> 0.42857143
A39: COST | D39: =SUM(D32:D35) -> 167.69321

Sheet Scotch Eggs
A1: Grasmere Farm Manual
A2: Product Page
A3: Scotch & Bacon Eggs
A4: INGREDIENTS | B4: . All allergens in BOLD.
A16: Product | B16: Scotch or Bacon Eggs | F16: Product | G16: Scotch or Bacon Eggs Individual Pack | K16: Product | L16: Scotch or Bacon Eggs Twin Pack
B17: Weight | C17: Cost | D17: Total | G17: Weight | H17: Cost | I17: Total | L17: Weight | M17: Cost | N17: Total
A18: Sausage Strip | B18: 0.088 | C18: ='Ingredient Cost'!D50 -> 56.25 | D18: =B18*C18 -> 4.95 | F18: Scotch/Bacon Egg | G18: 1 | H18: =D26 -> 5.3013 | I18: =G18*H18 -> 5.3013 | K18: Twin Pack | L18: 12 | M18: =D26 -> 5.3013 | N18: =L18*M18 -> 63.6156
A19: Egg | B19: 1 | C19: ='Ingredient Cost'!D16 -> 0.27 | D19: =B19*C19 -> 0.27 | F19: Packaging/Label | G19: 1 | H19: 0.02 | I19: =G19*H19 -> 0.02 | K19: Packaging | L19: 6 | M19: ='Ingredient Cost'!D88 -> 0.09 | N19: =SUM(L19*M19) -> 0.54
A20: Crumb | B20: 0.01 | C20: ='Ingredient Cost'!D17 -> 1.26 | D20: =B20*C20 -> 0.0126 | F20: Labour | G20: 240 | H20: 15 | I20: =H20/G20 -> 0.0625 | K20: Case | L20: 1 | M20: ='Ingredient Cost'!D108 -> 0.2 | N20: =L20*M20 -> 0.2
A21: Flour/Egg Wash | B21: 0.01 | C21: ='Ingredient Cost'!D7 -> 0.62 | D21: =B21*C21 -> 0.0062 | K21: Label | M21: 0.07 | N21: =M21 -> 0.07
A22: Labour | B22: 240 | C22: 15 | D22: =C22/B22 -> 0.0625 | K22: Labour | L22: 20 | M22: 15 | N22: =M22/L22 -> 0.75
A26: COST | D26: =SUM(D18:D22) -> 5.3013 | F26: COST | I26: =SUM(I18:I22) -> 5.3838 | K26: COST | N26: =SUM(N18:N22) -> 65.1756
K27: PER EGG | N27: =N26/6 -> 10.8626

Sheet ROM
A1: Grasmere Farm Manual
A2: Product Page
A3: Red Onion Marmalade
A4: INGREDIENTS | B4: . All allergens in BOLD.
A16: Product | B16: Red Onion Marmalade | G16: Product | H16: Sweet Chilli Red Onion Marmalade
B17: Weight | C17: Cost | D17: Total | H17: Weight | I17: Cost | J17: Total
A18: Red Onions | B18: 5 | C18: ='Ingredient Cost'!D32 -> 13.5 | D18: =B18*C18 -> 67.5 | G18: Red Onions | H18: 5 | I18: ='Ingredient Cost'!D32 -> 13.5 | J18: =H18*I18 -> 67.5
A19: Brown Sugar | B19: 3.5 | C19: ='Ingredient Cost'!D30 -> 1.02 | D19: =B19*C19 -> 3.57 | G19: Brown Sugar | H19: 3.5 | I19: =C19 -> 1.02 | J19: =H19*I19 -> 3.57
A20: Red wine Vinegar | B20: 1 | C20: ='Ingredient Cost'!D34 -> 5.27 | D20: =B20*C20 -> 5.27 | G20: Red wine Vinegar | H20: 1 | I20: =C20 -> 5.27 | J20: =H20*I20 -> 5.27
A21: Total | B21: =SUM(B18:B20) -> 9.5 | D21: =SUM(D18:D20) -> 76.34 | G21: Chilli Flakes | H21: 0.02 | I21: ='Ingredient Cost'!D35 -> 9.4 | J21: =H21*I21 -> 0.188
A22: Per Kg | D22: =D21/B21 -> 8.0357895 | G22: Total | H22: =SUM(H18:H21) -> 9.52 | J22: =SUM(J18:J21) -> 76.528
A23: Red Onion Marmalade | B23: 0.475 | C23: =D22 -> 8.0357895 | D23: =B23*C23 -> 3.817 | G23: Per KG | J23: =J22/H22 -> 8.0386555
A24: Jar | B24: 1 | C24: ='Ingredient Cost'!D102 -> 0.23 | D24: =B24*C24 -> 0.23 | G24: SWROM | H24: 0.475 | I24: =J23 -> 8.0386555 | J24: =H24*I24 -> 3.8183613
A25: Lid | B25: 1 | C25: ='Ingredient Cost'!D103 -> 0.006 | D25: =B25*C25 -> 0.006 | G25: Jar | H25: 1 | I25: =C24 -> 0.23 | J25: =H25*I25 -> 0.23
A26: Label | B26: 1 | C26: 0.01 | D26: =B26*C26 -> 0.01 | G26: Label | H26: 1 | I26: 0.01 | J26: =H26*I26 -> 0.01
A27: Labour | B27: 60 | C27: 15 | D27: =C27/B27 -> 0.25 | G27: Lid | H27: 1 | I27: =C25 -> 0.006 | J27: =H27*I27 -> 0.006
G28: Labour | H28: 60 | I28: 15 | J28: =I28/H28 -> 0.25
A30: COST | D30: =SUM(D23:D27) -> 4.313
G31: COST | J31: =SUM(J24:J28) -> 4.3143613
A33: Red Onion Marmalade Case
B34: Weight | C34: Cost | D34: Total
A35: ROM | B35: 12 | C35: =D30 -> 4.313 | D35: =B35*C35 -> 51.756
A36: Case | B36: 1 | C36: ='Ingredient Cost'!D108 -> 0.2 | D36: =B36*C36 -> 0.2
A37: Label | B37: 1 | C37: 0.01 | D37: =C37/B37 -> 0.01
A38: Labour | B38: 20 | C38: 15 | D38: =C38/B38 -> 0.75
A43: COST | D43: =SUM(D35:D41) -> 52.716

Sheet Pastry Costing
A1: Kitchen Pastry Costs
A2: Change info in yellow boxes
A4: Product | B4: Cold Water Pastry- Meat Pies Batch | F4: Product | G4: Hot Water Pastry- Pork Pies Batch
A5: Date | B5: ….. | F5: Date | G5: …..
B6: Weight | C6: Cost | D6: Total | G6: Weight | H6: Cost | I6: Total
A7: Water | B7: 2.5 | F7: Water | G7: 2.5
A8: Fat/Butter | B8: 4 | C8: ='Ingredient Cost'!$D$6 -> 2.06 | D8: =B8*C8 -> 8.24 | F8: Fat/Butter | G8: 4 | H8: ='Ingredient Cost'!$D$6 -> 2.06 | I8: =G8*H8 -> 8.24
A9: Flour | B9: 8 | C9: ='Ingredient Cost'!$D$7 -> 0.62 | D9: =B9*C9 -> 4.96 | F9: Flour | G9: 8 | H9: ='Ingredient Cost'!$D$7 -> 0.62 | I9: =G9*H9 -> 4.96
A10: Salt | B10: 0.15 | C10: ='Ingredient Cost'!$D$8 -> 0.54 | D10: =B10*C10 -> 0.081 | F10: Salt | G10: 0.15 | H10: ='Ingredient Cost'!$D$8 -> 0.54 | I10: =G10*H10 -> 0.081
A12: Total Weight | B12: =B7+B8+B9+B10 -> 14.65 | D12: =SUM(D7:D10) -> 13.281 | F12: Total Weight | G12: =G7+G8+G9+G10 -> 14.65 | I12: =SUM(I7:I10) -> 13.281
A14: COST | D14: =D12/B12 -> 0.9065529 | F14: COST | I14: =I12/G12 -> 0.9065529
A16: Small bases | B16: 150 | F16: Mini | G16: 225
A17: Medium bases | B17: 106 | F17: Small | G17: 120
A18: Large | B18: 65 | F18: Medium | G18: 70
F19: 2lb | G19: 30
F20: Large | G20: 24
A22: PORK PIES PASTRY COST | B22: Pie base weight | C22: Cost Open | D22: Pie Lid weight | E22: Lid Cost | F22: Total Cost
A23: Mini | B23: 0.065 | C23: =B23*I14 -> 0.058925939 | D23: 0.02 | E23: =D23*I14 -> 0.018131058 | F23: =C23+E23 -> 0.077056997
A24: 10oz | B24: 0.12 | C24: =B24*I14 -> 0.10878635 | D24: 0.04 | E24: =D24*I14 -> 0.036262116 | F24: =C24+E24 -> 0.14504846
A25: 1lb | B25: 0.21 | C25: =B25*I14 -> 0.19037611 | D25: 0.06 | E25: =D25*I14 -> 0.054393174 | F25: =C25+E25 -> 0.24476928
A26: 2lb | B26: 0.445 | C26: =B26*I14 -> 0.40341604 | D26: 0.06 | E26: =D26*I14 -> 0.054393174 | F26: =C26+E26 -> 0.45780922
A27: 3lb | B27: 0.445 | C27: =B27*I14 -> 0.40341604 | D27: 0.165 | E27: =D27*I14 -> 0.14958123 | F27: =C27+E27 -> 0.55299727
A29: MEAT PIE PASTRY COST | B29: Pie base weight | C29: Cost Open | D29: Pie Lid weight | E29: Lid Cost | F29: Total Cost
A30: Individual | B30: 0.097 | C30: =B30*D14 -> 0.087935631 | D30: 0.04 | E30: =D30*C37 -> 0.12285906 | F30: =C30+E30 -> 0.21079469
A31: Medium | B31: 0.138 | C31: =B31*D14 -> 0.1251043 | D31: 0.08 | E31: =D31*H37 -> 0.21631 | F31: =C31+E31 -> 0.3414143
A32: Large | B32: 0.225 | C32: =B32*D14 -> 0.2039744 | D32: 0.165 | E32: =D32*'Ingredient Cost'!D9 -> 0.3201 | F32: =C32+E32 -> 0.5240744
A35: Small Lid | B35: Weight | C35: Cost | D35: Total | F35: Medium lists | G35: Weight | H35: Cost | I35: Total | K35: Mixed lids | L35: Weight | M35: Cost | N35: Total
A36: Total Weight and Cost | B36: 10.766 | C36: ='Ingredient Cost'!D9 -> 1.94 | D36: =B36*C36 -> 20.88604 | F36: Total Weight and Cost | G36: 10.704 | H36: =C36 -> 1.94 | I36: =G36*H36 -> 20.76576 | K36: Total Weight and Cost | L36: 10.832 | M36: =H36 -> 1.94 | N36: =L36*M36 -> 21.01408
A37: 170 lids | B37: =0.04*170 -> 6.8 | C37: =D36/B37 -> 3.0714765 | D37: =B37*C37 -> 20.88604 | F37: 96 lids | G37: =0.08*96 -> 7.68 | H37: =I36/G37 -> 2.703875 | I37: =G37*H37 -> 20.76576 | K37: 36 small | L37: =0.04*36 -> 1.44 | M37: =N40 -> 2.6007525 | N37: =L37*M37 -> 3.7450836
A38: Waste | B38: 3.046 | C38: =C36 -> 1.94 | D38: =B38*C38 -> 5.90924 | F38: Waste | G38: 2.98 | H38: =H36 -> 1.94 | I38: =G38*H38 -> 5.7812 | K38: 83 medium | L38: =0.08*83 -> 6.64 | M38: =N40 -> 2.6007525 | N38: =L38*M38 -> 17.268996
K39: Waste | L39: 2.36 | M39: =M36 -> 1.94 | N39: =L39*M39 -> 4.5784
N40: =N36/(L37+L38) -> 2.6007525

Sheet Jumbo Sausage Roll
A1: Grasmere Farm Manual
A2: Product Page
A3: Jumbo Sausage Roll
A5: Product | B5: Strip costing | G5: Product | H5: Strip costing
B6: Weight | C6: Cost | D6: Total | H6: Weight | I6: Cost | J6: Total
A7: Pukka Pasty | B7: 11.056 | C7: ='Ingredient Cost'!D9 -> 1.94 | D7: =B7*C7 -> 21.44864 | G7: Pukka Pasty | H7: 11.102 | I7: =C7 -> 1.94 | J7: =H7*I7 -> 21.53788
A8: Sausagemeat | B8: 12.321 | C8: ='Ingredient Cost'!D50 -> 56.25 | D8: =B8*C8 -> 693.05625 | G8: Sausagemeat | H8: 12.321 | I8: =C8 -> 56.25 | J8: =H8*I8 -> 693.05625
A9: Waste | B9: 1.298 | C9: =D14 -> 32.361289 | D9: =C9/B9 -> 24.931655 | G9: Waste | H9: 1.362 | I9: =J14 -> 32.391738 | J9: =I9/H9 -> 23.78248
A10: Labour | B10: 275 | C10: ='Ingredient Cost'!J3 -> 20 | D10: =C10/B10 -> 0.072727273 | G10: Labour | H10: 275 | I10: =C10 -> 20 | J10: =I10/H10 -> 0.072727273
A14: COST | D14: =(D7+D8)/(B7+B8-B9) -> 32.361289 | E14: per kg | G14: COST | J14: =(J7+J8)/(H7+H8-H9) -> 32.391738 | K14: per kg
D15: =(D7+D8)/148 -> 4.8277357 | E15: each | J15: =(J7+J8)/148 -> 4.8283387 | K15: each
A17: Product | B17: Raw Jumbo Sausage Roll boxed
B18: Weight | C18: Cost | D18: Total
A19: Sausage Roll | B19: 48 | C19: =D15 -> 4.8277357 | D19: =B19*C19 -> 231.73132
A20: Case | B20: 1 | C20: ='Ingredient Cost'!D108 -> 0.2 | D20: =B20*C20 -> 0.2 | N20: 0.115
A21: Cooking Paper | B21: 2 | C21: ='Ingredient Cost'!D86 -> 0.12 | D21: =B21*C21 -> 0.24
A22: Label | B22: 1 | C22: 0.01 | D22: =C22/B22 -> 0.01
A26: COST | D26: =SUM(D19:D23) -> 232.18132
A27: PER EACH | D27: =D26/48 -> 4.8371107
A28: Product | B28: Cooked Jumbo Sausage Roll Single Pack Case
B29: Weight | C29: Cost | D29: Total
A30: Jumbo Sausage Roll | B30: 10 | C30: =D15 -> 4.8277357 | D30: =B30*C30 -> 48.277357
A31: Packaging | B31: 10 | C31: ='Ingredient Cost'!D88 -> 0.09 | D31: =SUM(B31*C31) -> 0.9
A32: Case | B32: 1 | C32: ='Ingredient Cost'!D108 -> 0.2 | D32: =B32*C32 -> 0.2
A33: Label | C33: 0.01 | D33: =C33 -> 0.01
A34: Labour | B34: 200 | C34: =C10 -> 20 | D34: =C34/B34 -> 0.1
A37: COST | D37: =SUM(D30:D34) -> 49.487357
A38: PER EACH | D38: =D37/10 -> 4.9487357

Sheet Costings v2
B1: Kitchen Costings
B2: 46054
E4: Required Margin: | F4: 0.15 | G4: (Indirect Expenses (10%) + 5%) | I4: Van Sales Margin | J4: 0.3
B6: Product | C6: Category | D6: Sub-Category | E6: Size (Meat Pie) | F6: COGS | G6: Kitchen Margin | H6: Kitchen Price | I6: Van Sales Margin | J6: Minimum Price | K6: Minimum Price Incl. VAT
B7: Jumbo Sausage Rolls - Raw 48 case | C7: Sausage Roll | D7: Case | F7: ='Jumbo Sausage Roll v2'!I51 -> 23.978649 | G7: =F$4 -> 0.15 | H7: =F7*(G7+1) -> 27.575446 | I7: =J$4 -> 0.3 | J7: =H7*(1+$J$4) -> 35.84808 | K7: =Table1[[#This Row],[Minimum Price]]*1.2 -> 43.017696
B8: Jumbo Sausage Rolls - Cooked 10 per case | C8: Sausage Roll | D8: Case | F8: ='Jumbo Sausage Roll v2'!D51 -> 7.3918018 | G8: =F$4 -> 0.15 | H8: =F8*(G8+1) -> 8.5005721 | I8: =J$4 -> 0.3 | J8: =H8*(1+$J$4) -> 11.050744 | K8: =Table1[[#This Row],[Minimum Price]]*1.2 -> 13.260892
B9: Jumbo Sausage Roll - Retail | C9: Sausage Roll | D9: Individual | F9: ='Jumbo Sausage Roll v2'!D40 -> 0.71018018 | G9: =F$4 -> 0.15 | H9: =F9*(G9+1) -> 0.81670721 | I9: =J$4 -> 0.3 | J9: =H9*(1+$J$4) -> 1.0617194 | K9: =Table1[[#This Row],[Minimum Price]]*1.2 -> 1.2740632
B10: Twin Sausage Rolls - Retail | C10: Sausage Roll | D10: Individual | F10: ='Sausage Roll v2'!D40 -> 1.0386937 | G10: =F$4 -> 0.15 | H10: =F10*(G10+1) -> 1.1944977 | I10: =J$4 -> 0.3 | J10: =H10*(1+$J$4) -> 1.5528471 | K10: =Table1[[#This Row],[Minimum Price]]*1.2 -> 1.8634165
B11: Twin Sausage Rolls - Cooked 10 per case | C11: Sausage Roll | D11: Case | F11: ='Sausage Roll v2'!D51 -> 10.676937 | G11: =F$4 -> 0.15 | H11: =F11*(G11+1) -> 12.278477 | I11: =J$4 -> 0.3 | J11: =H11*(1+$J$4) -> 15.962021 | K11: =Table1[[#This Row],[Minimum Price]]*1.2 -> 19.154425
B12: Steak Pie - Cooked | C12: Meat Pie | D12: Individual | E12: Small | F12: ='Steak Pie v2'!D54 -> 1.387782 | G12: =F$4 -> 0.15 | H12: =F12*(G12+1) -> 1.5959493 | I12: =J$4 -> 0.3 | J12: =H12*(1+$J$4) -> 2.0747341 | K12: =Table1[[#This Row],[Minimum Price]]*1.2 -> 2.4896809
B13: Steak Pie - Cooked (not packaged) | C13: Meat Pie | D13: Individual | E13: Small | F13: ='Steak Pie v2'!D35+'Steak Pie v2'!D53 -> 1.237782 | G13: =F$4 -> 0.15 | H13: =F13*(G13+1) -> 1.4234493 | I13: =J$4 -> 0.3 | J13: =H13*(1+$J$4) -> 1.8504841 | K13: =Table1[[#This Row],[Minimum Price]]*1.2 -> 2.2205809
B14: Steak Pie - Cooked case of 6 | C14: Meat Pie | D14: Case | E14: Small | F14: ='Steak Pie v2'!D74 -> 8.6478031 | G14: =F$4 -> 0.15 | H14: =F14*(G14+1) -> 9.9449736 | I14: =J$4 -> 0.3 | J14: =H14*(1+$J$4) -> 12.928466 | K14: =Table1[[#This Row],[Minimum Price]]*1.2 -> 15.514159
B15: Steak Pie - Cooked case of 9 | C15: Meat Pie | D15: Case | E15: Small | F15: ='Steak Pie v2'!D65 -> 12.811149 | G15: =F$4 -> 0.15 | H15: =F15*(G15+1) -> 14.732822 | I15: =J$4 -> 0.3 | J15: =H15*(1+$J$4) -> 19.152668 | K15: =Table1[[#This Row],[Minimum Price]]*1.2 -> 22.983202
B16: Steak Pie - Frozen case of 12 | C16: Meat Pie | D16: Case | E16: Small | F16: ='Steak Pie v2'!D83 -> 15.174495 | G16: =F$4 -> 0.15 | H16: =F16*(G16+1) -> 17.450669 | I16: =J$4 -> 0.3 | J16: =H16*(1+$J$4) -> 22.68587 | K16: =Table1[[#This Row],[Minimum Price]]*1.2 -> 27.223044
B17: Steak Pie - Cooked | C17: Meat Pie | D17: Individual | E17: Medium | F17: ='Steak Pie v2'!I54 -> 2.5601668 | G17: =F$4 -> 0.15 | H17: =F17*(G17+1) -> 2.9441918 | I17: =J$4 -> 0.3 | J17: =H17*(1+$J$4) -> 3.8274494 | K17: =Table1[[#This Row],[Minimum Price]]*1.2 -> 4.5929393
B18: Steak Pie - Frozen | C18: Meat Pie | D18: Individual | E18: Medium | F18: ='Steak Pie v2'!I54 -> 2.5601668 | G18: =F$4 -> 0.15 | H18: =F18*(G18+1) -> 2.9441918 | I18: =J$4 -> 0.3 | J18: =H18*(1+$J$4) -> 3.8274494 | K18: =Table1[[#This Row],[Minimum Price]]*1.2 -> 4.5929393
B19: Steak Pie - Cooked Case of 4 | C19: Meat Pie | D19: Case | E19: Medium | F19: ='Steak Pie v2'!I65 -> 10.561778 | G19: =F$4 -> 0.15 | H19: =F19*(G19+1) -> 12.146045 | I19: =J$4 -> 0.3 | J19: =H19*(1+$J$4) -> 15.789859 | K19: =Table1[[#This Row],[Minimum Price]]*1.2 -> 18.94783
B20: Steak Pie - Frozen | C20: Meat Pie | D20: Individual | E20: Large | F20: ='Steak Pie v2'!N54 -> 5.3284461 | G20: =F$4 -> 0.15 | H20: =F20*(G20+1) -> 6.127713 | I20: =J$4 -> 0.3 | J20: =H20*(1+$J$4) -> 7.9660269 | K20: =Table1[[#This Row],[Minimum Price]]*1.2 -> 9.5592323
B21: Steak & Ale Pie - Cooked | C21: Meat Pie | D21: Individual | E21: Small | F21: ='Steak & Ale Pie v2'!D54 -> 1.4129884 | G21: =F$4 -> 0.15 | H21: =F21*(G21+1) -> 1.6249366 | I21: =J$4 -> 0.3 | J21: =H21*(1+$J$4) -> 2.1124176 | K21: =Table1[[#This Row],[Minimum Price]]*1.2 -> 2.5349011
B22: Steak & Ale Pie - Cooked case of 6 | C22: Meat Pie | D22: Case | E22: Small | F22: ='Steak & Ale Pie v2'!D74 -> 8.7990414 | G22: =F$4 -> 0.15 | H22: =F22*(G22+1) -> 10.118898 | I22: =J$4 -> 0.3 | J22: =H22*(1+$J$4) -> 13.154567 | K22: =Table1[[#This Row],[Minimum Price]]*1.2 -> 15.78548
B23: Steak & Ale Pie - Cooked case of 9 | C23: Meat Pie | D23: Case | E23: Small | F23: ='Steak & Ale Pie v2'!D65 -> 13.038007 | G23: =F$4 -> 0.15 | H23: =F23*(G23+1) -> 14.993707 | I23: =J$4 -> 0.3 | J23: =H23*(1+$J$4) -> 19.49182 | K23: =Table1[[#This Row],[Minimum Price]]*1.2 -> 23.390184
B24: Steak & Ale Pie - Cooked case of 12 | C24: Meat Pie | D24: Case | E24: Small | F24: ='Steak & Ale Pie v2'!D83 -> 17.276972 | G24: =F$4 -> 0.15 | H24: =F24*(G24+1) -> 19.868517 | I24: =J$4 -> 0.3 | J24: =H24*(1+$J$4) -> 25.829073 | K24: =Table1[[#This Row],[Minimum Price]]*1.2 -> 30.994887
B25: Steak & Ale Pie - Cooked | C25: Meat Pie | D25: Individual | E25: Medium | F25: ='Steak & Ale Pie v2'!I54 -> 2.6103842 | G25: =F$4 -> 0.15 | H25: =F25*(G25+1) -> 3.0019418 | I25: =J$4 -> 0.3 | J25: =H25*(1+$J$4) -> 3.9025243 | K25: =Table1[[#This Row],[Minimum Price]]*1.2 -> 4.6830292
B26: Steak & Ale Pie - Frozen | C26: Meat Pie | D26: Individual | E26: Medium | F26: ='Steak & Ale Pie v2'!I54 -> 2.6103842 | G26: =F$4 -> 0.15 | H26: =F26*(G26+1) -> 3.0019418 | I26: =J$4 -> 0.3 | J26: =H26*(1+$J$4) -> 3.9025243 | K26: =Table1[[#This Row],[Minimum Price]]*1.2 -> 4.6830292
B27: Steak & Ale Pie - Cooked case of 4 | C27: Meat Pie | D27: Case | E27: Medium | F27: ='Steak & Ale Pie v2'!I65 -> 10.762648 | G27: =F$4 -> 0.15 | H27: =F27*(G27+1) -> 12.377045 | I27: =J$4 -> 0.3 | J27: =H27*(1+$J$4) -> 16.090158 | K27: =Table1[[#This Row],[Minimum Price]]*1.2 -> 19.30819
B28: Steak & Ale Pie - Frozen | C28: Meat Pie | D28: Individual | E28: Large | F28: ='Steak & Ale Pie v2'!N54 -> 5.4730408 | G28: =F$4 -> 0.15 | H28: =F28*(G28+1) -> 6.2939969 | I28: =J$4 -> 0.3 | J28: =H28*(1+$J$4) -> 8.182196 | K28: =Table1[[#This Row],[Minimum Price]]*1.2 -> 9.8186351
B29: Steak & Kidney Pie - Cooked | C29: Meat Pie | D29: Individual | E29: Small | F29: ='Steak & Kidney Pie v2'!D54 -> 1.3250837 | G29: =F$4 -> 0.15 | H29: =F29*(G29+1) -> 1.5238462 | I29: =J$4 -> 0.3 | J29: =H29*(1+$J$4) -> 1.9810001 | K29: =Table1[[#This Row],[Minimum Price]]*1.2 -> 2.3772001
B30: Steak & Kidney Pie - Cooked case of 6 | C30: Meat Pie | D30: Case | E30: Small | F30: ='Steak & Kidney Pie v2'!D74 -> 8.2716131 | G30: =F$4 -> 0.15 | H30: =F30*(G30+1) -> 9.5123551 | I30: =J$4 -> 0.3 | J30: =H30*(1+$J$4) -> 12.366062 | K30: =Table1[[#This Row],[Minimum Price]]*1.2 -> 14.839274
B31: Steak & Kidney Pie - Cooked case of 9 | C31: Meat Pie | D31: Case | E31: Small | F31: ='Steak & Kidney Pie v2'!D65 -> 12.246864 | G31: =F$4 -> 0.15 | H31: =F31*(G31+1) -> 14.083894 | I31: =J$4 -> 0.3 | J31: =H31*(1+$J$4) -> 18.309062 | K31: =Table1[[#This Row],[Minimum Price]]*1.2 -> 21.970874
B32: Steak & Kidney Pie - Cooked case of 12 | C32: Meat Pie | D32: Case | E32: Small | F32: ='Steak & Kidney Pie v2'!D83 -> 16.222115 | G32: =F$4 -> 0.15 | H32: =F32*(G32+1) -> 18.655432 | I32: =J$4 -> 0.3 | J32: =H32*(1+$J$4) -> 24.252062 | K32: =Table1[[#This Row],[Minimum Price]]*1.2 -> 29.102474
B33: Steak & Kidney Pie - Cooked | C33: Meat Pie | D33: Individual | E33: Medium | F33: ='Steak & Kidney Pie v2'!I54 -> 2.4352562 | G33: =F$4 -> 0.15 | H33: =F33*(G33+1) -> 2.8005446 | I33: =J$4 -> 0.3 | J33: =H33*(1+$J$4) -> 3.640708 | K33: =Table1[[#This Row],[Minimum Price]]*1.2 -> 4.3688495
B34: Steak & Kidney Pie - Frozen | C34: Meat Pie | D34: Individual | E34: Medium | F34: ='Steak & Kidney Pie v2'!I54 -> 2.4352562 | G34: =F$4 -> 0.15 | H34: =F34*(G34+1) -> 2.8005446 | I34: =J$4 -> 0.3 | J34: =H34*(1+$J$4) -> 3.640708 | K34: =Table1[[#This Row],[Minimum Price]]*1.2 -> 4.3688495
B35: Steak & Kidney Pie - Cooked case of 4 | C35: Meat Pie | D35: Case | E35: Medium | F35: ='Steak & Kidney Pie v2'!I65 -> 10.062136 | G35: =F$4 -> 0.15 | H35: =F35*(G35+1) -> 11.571456 | I35: =J$4 -> 0.3 | J35: =H35*(1+$J$4) -> 15.042893 | K35: =Table1[[#This Row],[Minimum Price]]*1.2 -> 18.051472
B36: Steak & Kidney Pie - Frozen | C36: Meat Pie | D36: Individual | E36: Large | F36: ='Steak & Kidney Pie v2'!N54 -> 4.9687812 | G36: =F$4 -> 0.15 | H36: =F36*(G36+1) -> 5.7140983 | I36: =J$4 -> 0.3 | J36: =H36*(1+$J$4) -> 7.4283278 | K36: =Table1[[#This Row],[Minimum Price]]*1.2 -> 8.9139934
B37: Steak & Stilton Pie - Cooked | C37: Meat Pie | D37: Individual | E37: Small | F37: ='Steak & Stilton Pie v2'!D55 -> 1.5045816 | G37: =F$4 -> 0.15 | H37: =F37*(G37+1) -> 1.7302688 | I37: =J$4 -> 0.3 | J37: =H37*(1+$J$4) -> 2.2493494 | K37: =Table1[[#This Row],[Minimum Price]]*1.2 -> 2.6992193
B38: Steak & Stilton Pie - Cooked case of 6 | C38: Meat Pie | D38: Case | E38: Small | F38: ='Steak & Stilton Pie v2'!D75 -> 9.3486005 | G38: =F$4 -> 0.15 | H38: =F38*(G38+1) -> 10.750891 | I38: =J$4 -> 0.3 | J38: =H38*(1+$J$4) -> 13.976158 | K38: =Table1[[#This Row],[Minimum Price]]*1.2 -> 16.771389
B39: Steak & Stilton Pie - Cooked case of 9 | C39: Meat Pie | D39: Case | E39: Small | F39: ='Steak & Stilton Pie v2'!D66 -> 13.862345 | G39: =F$4 -> 0.15 | H39: =F39*(G39+1) -> 15.941697 | I39: =J$4 -> 0.3 | J39: =H39*(1+$J$4) -> 20.724206 | K39: =Table1[[#This Row],[Minimum Price]]*1.2 -> 24.869047
B40: Steak & Stilton Pie - Cooked case of 12 | C40: Meat Pie | D40: Case | E40: Small | F40: ='Steak & Stilton Pie v2'!D84 -> 18.37609 | G40: =F$4 -> 0.15 | H40: =F40*(G40+1) -> 21.132503 | I40: =J$4 -> 0.3 | J40: =H40*(1+$J$4) -> 27.472254 | K40: =Table1[[#This Row],[Minimum Price]]*1.2 -> 32.966705
B41: Steak & Stilton Pie - Cooked | C41: Meat Pie | D41: Individual | E41: Medium | F41: ='Steak & Stilton Pie v2'!I55 -> 2.7221628 | G41: =F$4 -> 0.15 | H41: =F41*(G41+1) -> 3.1304872 | I41: =J$4 -> 0.3 | J41: =H41*(1+$J$4) -> 4.0696334 | K41: =Table1[[#This Row],[Minimum Price]]*1.2 -> 4.8835601
B42: Steak & Stilton Pie - Frozen | C42: Meat Pie | D42: Individual | E42: Medium | F42: ='Steak & Stilton Pie v2'!I55 -> 2.7221628 | G42: =F$4 -> 0.15 | H42: =F42*(G42+1) -> 3.1304872 | I42: =J$4 -> 0.3 | J42: =H42*(1+$J$4) -> 4.0696334 | K42: =Table1[[#This Row],[Minimum Price]]*1.2 -> 4.8835601
...

Sheet Sliced Haslet - 120g
A1: Grasmere Farm
A2: Product Costings
A3: Sliced Haslet - 120g
A4: INGREDIENTS | B4: . All allergens in BOLD.
A17: Ingredient Cost
B19: Cost | C19: Yield | D19: Total | F19: Shrinkage Calculation
A20: Sausage Meat | B20: ='Ingredient Cost'!D57 -> 61.36 | C20: 108 | D20: =B20/C20 -> 0.56814815 | F20: Start Weight | G20: =6*0.454 -> 2.724
A21: Vale Fat | B21: ='Ingredient Cost'!D78 -> 2.25 | C21: 0.2 | D21: =C21/B21 -> 0.088888889 | F21: Cook Shrinkage (90%) | G21: =G20*0.9 -> 2.4516
D22: =SUM(D20:D21) -> 0.65703704 | F22: Slice Yielf (90%) | G22: =G21*0.9 -> 2.20644
F23: Packs per Haslet | G23: =G22/0.12 -> 18.387 | H23: 18 | I23: per haslet | J23: =H23*6 -> 108 | K23: per tray
A25: Individual Packaged Products (excl. Labour)
A27: Individual
B28: Weight | C28: Cost | D28: Total
A29: Ingredient Cost | B29: 1 | C29: =D22 -> 0.65703704 | D29: =B29*C29 -> 0.65703704
A30: Packaging | B30: 1 | C30: ='Ingredient Cost'!D88 -> 0.09 | D30: =C30*B30 -> 0.09
A31: COST | D31: =SUM(D29:D30) -> 0.74703704
A34: Individual Packaged Products (incl. Labour) | D34: = | E34: COGS
A36: Individual
B37: Weight | C37: Cost | D37: Total
A38: Packaged Product Cost | B38: 1 | C38: =D31 -> 0.74703704 | D38: =B38*C38 -> 0.74703704
A39: Labour | B39: 55 | C39: ='Ingredient Cost'!$B$113 -> 20 | D39: =C39/B39 -> 0.36363636
A40: COST | D40: =SUM(D38:D39) -> 1.1106734
B42: Labour Percentage | D42: =D39/D38 -> 0.48677153
A43: CASES
A45: Case of 6
B46: Weight | C46: Cost | D46: Total
A47: Product Cost | B47: 6 | C47: =D40 -> 1.1106734 | D47: =B47*C47 -> 6.6640404
A48: Case Packaging | B48: 1 | C48: ='Ingredient Cost'!$D$108 -> 0.2 | D48: =B48*C48 -> 0.2
A49: Labour | B49: 250 | C49: =$C$39 -> 20 | D49: =C49/B49 -> 0.08
A50: Box end label | B50: 1 | C50: 0.01 | D50: =B50*C50 -> 0.01
A51: COST | D51: =SUM(D47:D50) -> 6.9540404
A52: PER EACH | D52: =D51/6 -> 1.1590067
A54: Case of 12
B55: Weight | C55: Cost | D55: Total
A56: Product Cost | B56: 12 | C56: =D40 -> 1.1106734 | D56: =B56*C56 -> 13.328081
A57: Case Packaging | B57: 1 | C57: ='Ingredient Cost'!$D$108 -> 0.2 | D57: =B57*C57 -> 0.2
A58: Labour | B58: 250 | C58: =$C$39 -> 20 | D58: =C58/B58 -> 0.08
A59: Box end label | B59: 1 | C59: 0.01 | D59: =B59*C59 -> 0.01
A60: COST | D60: =SUM(D56:D59) -> 13.618081
A61: PER EACH | D61: =D60/12 -> 1.1348401

Sheet Sliced Haslet - 160g
A1: Grasmere Farm
A2: Product Costings
A3: Sliced Haslet - 160g
A4: INGREDIENTS | B4: . All allergens in BOLD.
A17: Ingredient Cost
B19: Cost | C19: Yield | D19: Total | F19: Shrinkage Calculation
A20: Sausage Meat | B20: ='Ingredient Cost'!D57 -> 61.36 | C20: 78 | D20: =B20/C20 -> 0.78666667 | F20: Start Weight | G20: =6*0.454 -> 2.724
A21: Vale Fat | B21: ='Ingredient Cost'!D78 -> 2.25 | C21: 0.2 | D21: =C21/B21 -> 0.088888889 | F21: Cook Shrinkage (90%) | G21: =G20*0.9 -> 2.4516
D22: =SUM(D20:D21) -> 0.87555556 | F22: Slice Yielf (90%) | G22: =G21*0.9 -> 2.20644
F23: Packs per Haslet | G23: =G22/0.165 -> 13.372364 | H23: 13 | I23: per haslet | J23: =13*6 -> 78 | K23: per tray
A25: Individual Packaged Products (excl. Labour)
A27: Individual
B28: Weight | C28: Cost | D28: Total
A29: Ingredient Cost | B29: 1 | C29: =D22 -> 0.87555556 | D29: =B29*C29 -> 0.87555556
A30: Packaging | B30: 1 | C30: ='Ingredient Cost'!D88 -> 0.09 | D30: =C30*B30 -> 0.09
A31: COST | D31: =SUM(D29:D30) -> 0.96555556
A34: Individual Packaged Products (incl. Labour) | D34: = | E34: COGS
A36: Individual
B37: Weight | C37: Cost | D37: Total
A38: Packaged Product Cost | B38: 1 | C38: =D31 -> 0.96555556 | D38: =B38*C38 -> 0.96555556
A39: Labour | B39: 55 | C39: ='Ingredient Cost'!$B$113 -> 20 | D39: =C39/B39 -> 0.36363636
A40: COST | D40: =SUM(D38:D39) -> 1.3291919
B42: Labour Percentage | D42: =D39/D38 -> 0.37660843
A43: CASES
A45: Case of 6
B46: Weight | C46: Cost | D46: Total
A47: Product Cost | B47: 6 | C47: =D40 -> 1.3291919 | D47: =B47*C47 -> 7.9751515
A48: Case Packaging | B48: 1 | C48: ='Ingredient Cost'!$D$108 -> 0.2 | D48: =B48*C48 -> 0.2
A49: Labour | B49: 250 | C49: =$C$39 -> 20 | D49: =C49/B49 -> 0.08
A50: Box end label | B50: 1 | C50: 0.01 | D50: =B50*C50 -> 0.01
A51: COST | D51: =SUM(D47:D50) -> 8.2651515
A52: PER EACH | D52: =D51/6 -> 1.3775253
A54: Case of 12
B55: Weight | C55: Cost | D55: Total
A56: Product Cost | B56: 12 | C56: =D40 -> 1.3291919 | D56: =B56*C56 -> 15.950303
A57: Case Packaging | B57: 1 | C57: ='Ingredient Cost'!$D$108 -> 0.2 | D57: =B57*C57 -> 0.2
A58: Labour | B58: 250 | C58: =$C$39 -> 20 | D58: =C58/B58 -> 0.08
A59: Box end label | B59: 1 | C59: 0.01 | D59: =B59*C59 -> 0.01
A60: COST | D60: =SUM(D56:D59) -> 16.240303
A61: PER EACH | D61: =D60/12 -> 1.3533586

Sheet Whole Haslet v2
A1: Grasmere Farm
A2: Product Costings
A3: Whole Haslet
A4: INGREDIENTS | B4: . All allergens in BOLD.
A17: Ingredient Cost
B19: Cost | C19: Yield | D19: Total
A20: Sausage Meat | B20: ='Ingredient Cost'!D57 -> 61.36 | C20: 36 | D20: =B20/C20 -> 1.7044444
A21: Vale Fat | B21: ='Ingredient Cost'!D78 -> 2.25 | C21: 0.03 | D21: =C21/B21 -> 0.013333333
D22: =SUM(D20:D21) -> 1.7177778
A25: Individual Packaged Products (excl. Labour)
A27: Individual
B28: Weight | C28: Cost | D28: Total
A29: Ingredient Cost | B29: 1 | C29: =D22 -> 1.7177778 | D29: =B29*C29 -> 1.7177778
A30: Packaging | B30: 1 | C30: ='Ingredient Cost'!D88 -> 0.09 | D30: =C30*B30 -> 0.09
A31: COST | D31: =SUM(D29:D30) -> 1.8077778
A34: Individual Packaged Products (incl. Labour) | D34: = | E34: COGS
A36: Individual
B37: Weight | C37: Cost | D37: Total
A38: Packaged Product Cost | B38: 1 | C38: =D31 -> 1.8077778 | D38: =B38*C38 -> 1.8077778
A39: Labour | B39: 55 | C39: ='Ingredient Cost'!$B$113 -> 20 | D39: =C39/B39 -> 0.36363636
A40: COST | D40: =SUM(D38:D39) -> 2.1714141
B42: Labour Percentage | D42: =D39/D38 -> 0.20115103
A43: CASES
A45: Case of 6
B46: Weight | C46: Cost | D46: Total
A47: Product Cost | B47: 6 | C47: =D40 -> 2.1714141 | D47: =B47*C47 -> 13.028485
A48: Case Packaging | B48: 1 | C48: ='Ingredient Cost'!D108 -> 0.2 | D48: =B48*C48 -> 0.2
A49: Labour | B49: 250 | C49: =C39 -> 20 | D49: =C49/B49 -> 0.08
A50: Box end label | B50: 1 | C50: 0.01 | D50: =B50*C50 -> 0.01
A51: COST | D51: =SUM(D47:D50) -> 13.318485
A52: PER EACH | D52: =D51/6 -> 2.2197475

Sheet Scoth Eggs v2
A1: Grasmere Farm
A2: Product Costings
A3: Scotch Eggs
A4: INGREDIENTS | B4: . All allergens in BOLD.
A17: Ingredient Cost
B19: Cost | C19: Yield | D19: Total
A20: Scotch Meat | B20: ='Ingredient Cost'!D54 -> 0.34 | C20: 1 | D20: =B20/C20 -> 0.34
A21: Egg | B21: ='Ingredient Cost'!D16 -> 0.27 | C21: 1 | D21: =B21/C21 -> 0.27
A22: Crumb | B22: ='Ingredient Cost'!D17 -> 1.26 | C22: 60 | D22: =B22/C22 -> 0.021
A23: Egg Wash / Flour | B23: ='Ingredient Cost'!D7 -> 0.62 | C23: 30 | D23: =B23/C23 -> 0.020666667
D24: =SUM(D20:D23) -> 0.65166667
A27: Individual Packaged Products (excl. Labour)
A29: Individual | F29: Twin
B30: Weight | C30: Cost | D30: Total | G30: Weight | H30: Cost | I30: Total
A31: Ingredient Cost | B31: 1 | C31: =D24 -> 0.65166667 | D31: =B31*C31 -> 0.65166667 | F31: Ingredient Cost | G31: 2 | H31: =D24 -> 0.65166667 | I31: =G31*H31 -> 1.3033333
A32: Packaging | B32: 1 | C32: 0.02 | D32: =C32*B32 -> 0.02 | F32: Packaging | G32: 1 | H32: ='Ingredient Cost'!D88 -> 0.09 | I32: =H32*G32 -> 0.09
A33: COST | D33: =SUM(D31:D32) -> 0.67166667 | F33: COST | I33: =SUM(I31:I32) -> 1.3933333
A36: Individual Packaged Products (incl. Labour) | D36: = | E36: COGS
A38: Individual | F38: Twin
B39: Weight | C39: Cost | D39: Total | G39: Weight | H39: Cost | I39: Total
A40: Packaged Product Cost | B40: 1 | C40: =D33 -> 0.67166667 | D40: =B40*C40 -> 0.67166667 | F40: Packaged Product Cost | G40: 1 | H40: =I33 -> 1.3933333 | I40: =G40*H40 -> 1.3933333
A41: Labour | B41: 100 | C41: ='Ingredient Cost'!$B$113 -> 20 | D41: =C41/B41 -> 0.2 | F41: Labour | G41: 100 | H41: ='Ingredient Cost'!$B$113 -> 20 | I41: =H41/G41 -> 0.2
A42: COST | D42: =SUM(D40:D41) -> 0.87166667 | F42: COST | I42: =SUM(I40:I41) -> 1.5933333
B44: Labour Percentage | D44: =D41/D40 -> 0.29776675
A45: CASES
A47: Individual x6 | F47: Twin x6
B48: Weight | C48: Cost | D48: Total | G48: Weight | H48: Cost | I48: Total
A49: Product Cost | B49: 6 | C49: =D42 -> 0.87166667 | D49: =B49*C49 -> 5.23 | F49: Product Cost | G49: 6 | H49: =I42 -> 1.5933333 | I49: =G49*H49 -> 9.56
A50: Case Packaging | B50: 1 | C50: ='Ingredient Cost'!D108 -> 0.2 | D50: =B50*C50 -> 0.2 | F50: Case Packaging | G50: 1 | H50: ='Ingredient Cost'!D108 -> 0.2 | I50: =G50*H50 -> 0.2
A51: Labour | B51: 250 | C51: =C41 -> 20 | D51: =C51/B51 -> 0.08 | F51: Labour | G51: 250 | H51: =C41 -> 20 | I51: =H51/G51 -> 0.08
A52: Box end label | B52: 1 | C52: 0.01 | D52: =B52*C52 -> 0.01 | F52: Box end label | G52: 1 | H52: 0.01 | I52: =G52*H52 -> 0.01
A53: COST | D53: =SUM(D49:D52) -> 5.52 | F53: COST | I53: =SUM(I49:I52) -> 9.85
A54: PER EACH | D54: =D53/6 -> 0.92 | F54: PER EACH | I54: =I53/6 -> 1.6416667
A56: Individual x9 | F56: Twin x9
B57: Weight | C57: Cost | D57: Total | G57: Weight | H57: Cost | I57: Total
A58: Product Cost | B58: 9 | C58: =D42 -> 0.87166667 | D58: =B58*C58 -> 7.845 | F58: Product Cost | G58: 9 | H58: =I42 -> 1.5933333 | I58: =G58*H58 -> 14.34
A59: Case Packaging | B59: 1 | C59: ='Ingredient Cost'!D108 -> 0.2 | D59: =B59*C59 -> 0.2 | F59: Case Packaging | G59: 1 | H59: ='Ingredient Cost'!D108 -> 0.2 | I59: =G59*H59 -> 0.2
A60: Labour | B60: 250 | C60: =C41 -> 20 | D60: =C60/B60 -> 0.08 | F60: Labour | G60: 250 | H60: =C41 -> 20 | I60: =H60/G60 -> 0.08
A61: Box end label | B61: 1 | C61: 0.01 | D61: =B61*C61 -> 0.01 | F61: Box end label | G61: 1 | H61: 0.01 | I61: =G61*H61 -> 0.01
A62: COST | D62: =SUM(D58:D61) -> 8.135 | F62: COST | I62: =SUM(I58:I61) -> 14.63
...

Sheet Jumbo Sausage Roll v2
A1: Grasmere Farm
A2: Product Costings
A3: Jumbo Sausage Roll
A4: INGREDIENTS | B4: . All allergens in BOLD.
A17: Ingredient Cost
B19: Cost | C19: Yield | D19: Total
A20: Strips | B20: 56.25 | C20: 180 | D20: =B20/C20 -> 0.3125
A21: Pukka Pastry (roll) | B21: 20.87 | C21: 148 | D21: =B21/C21 -> 0.14101351
D22: =SUM(D20:D21) -> 0.45351351
A25: Individual Packaged Products (excl. Labour)
A27: Small - Cooked
B28: Weight | C28: Cost | D28: Total
A29: Ingredient Cost | B29: 1 | C29: =D22 -> 0.45351351 | D29: =B29*C29 -> 0.45351351
A30: Packaging | B30: 1 | C30: 0.09 | D30: =C30*B30 -> 0.09
A31: COST | D31: =SUM(D29:D30) -> 0.54351351
A34: Individual Packaged Products (incl. Labour) | D34: = | E34: COGS
A36: Jumbo
B37: Weight | C37: Cost | D37: Total
A38: Packaged Product Cost | B38: 1 | C38: =D31 -> 0.54351351 | D38: =B38*C38 -> 0.54351351
A39: Labour | B39: 120 | C39: ='Ingredient Cost'!$B$113 -> 20 | D39: =C39/B39 -> 0.16666667
A40: COST | D40: =SUM(D38:D39) -> 0.71018018
B42: Labour Percentage | D42: =D39/D38 -> 0.30664678
A43: CASES
A45: 10 per case | F45: 48* Box
B46: Weight | C46: Cost | D46: Total | G46: Weight | H46: Cost | I46: Total
A47: Product Cost | B47: 10 | C47: =D40 -> 0.71018018 | D47: =B47*C47 -> 7.1018018 | F47: Product Cost | G47: 48 | H47: =D22 -> 0.45351351 | I47: =G47*H47 -> 21.768649
A48: Case Packaging | B48: 1 | C48: ='Ingredient Cost'!D108 -> 0.2 | D48: =B48*C48 -> 0.2 | F48: Case Packaging | G48: 1 | H48: ='Ingredient Cost'!D108 -> 0.2 | I48: =G48*H48 -> 0.2
A49: Labour | B49: 250 | C49: =C39 -> 20 | D49: =C49/B49 -> 0.08 | F49: Labour | G49: 40 | H49: =C39 -> 20 | I49: =G49/H49 -> 2
A50: Box end label | B50: 1 | C50: 0.01 | D50: =B50*C50 -> 0.01 | F50: Box end label | G50: 1 | H50: 0.01 | I50: =G50*H50 -> 0.01
A51: COST | D51: =SUM(D47:D50) -> 7.3918018 | F51: COST | I51: =SUM(I47:I50) -> 23.978649
A52: PER EACH | D52: =D51/9 -> 0.82131131 | F52: PER EACH | I52: =I51/48 -> 0.49955518

Sheet Sausage Roll
A1: Grasmere Farm Manual
A2: Product Page
A3: Sausage Roll
A4: INGREDIENTS | B4: . All allergens in BOLD.
A16: Product | B16: Raw Small Sausage Roll | F16: Product | G16: Raw Small Sausage Roll boxed | K16: Product | L16: Raw Flavoured Sausage Roll boxed
B17: Weight | C17: Cost | D17: Total | G17: Weight | H17: Cost | I17: Total | L17: Weight | M17: Cost | N17: Total
A18: Sausage Strip | B18: 0.091 | C18: ='Ingredient Cost'!D50 -> 56.25 | D18: =B18*C18 -> 5.11875 | F18: Sausage Roll | G18: 60 | H18: =D24 -> 5.2107645 | I18: =G18*H18 -> 312.64587 | K18: Sausage Roll | L18: 32 | M18: =D24 -> 5.2107645 | N18: =L18*M18 -> 166.74447
A19: Pukka Pasty | B19: 0.024 | C19: ='Ingredient Cost'!D9 -> 1.94 | D19: =B19*C19 -> 0.04656 | F19: Case | G19: 1 | H19: ='Ingredient Cost'!D109 -> 0.27 | I19: =G19*H19 -> 0.27 | K19: Case | L19: 1 | M19: ='Ingredient Cost'!D108 -> 0.2 | N19: =L19*M19 -> 0.2
A20: Labour | B20: 330 | C20: 15 | D20: =C20/B20 -> 0.045454545 | F20: Cooking Paper | G20: 2 | H20: ='Ingredient Cost'!D86 -> 0.12 | I20: =G20*H20 -> 0.24 | K20: Cooking Paper | L20: 2 | M20: ='Ingredient Cost'!D86 -> 0.12 | N20: =L20*M20 -> 0.24
F21: Label | G21: 1 | H21: 0.01 | I21: =H21/G21 -> 0.01 | K21: Label | L21: 1 | M21: 0.01 | N21: =M21/L21 -> 0.01
F22: Labour | G22: 6 | H22: 15 | I22: =H22/G22 -> 2.5 | K22: Labour | L22: 8 | M22: 15 | N22: =M22/L22 -> 1.875
A24: COST | D24: =SUM(D18:D20) -> 5.2107645
F25: COST | I25: =SUM(I18:I22) -> 315.66587 | K25: COST | N25: =SUM(N18:N22) -> 169.06947
F26: PER EACH | I26: =I25/60 -> 5.2610979 | K26: PER EACH | N26: =N25/32 -> 5.2834208
A28: Product | B28: Cooked Small Sausage Roll Twin Pack
B29: Weight | C29: Cost | D29: Total
A30: Twin Packs | B30: 8 | C30: =D24*2 -> 10.421529 | D30: =B30*C30 -> 83.372233
A31: Cooking Paper | C31: ='Ingredient Cost'!D86 -> 0.12 | D31: =C31 -> 0.12
A32: Packaging | B32: 8 | C32: ='Ingredient Cost'!D90 -> 0.22 | D32: =B32*C32 -> 1.76
A33: Case | C33: ='Ingredient Cost'!D109 -> 0.27 | D33: =C33 -> 0.27
A34: Label | C34: 0.05 | D34: =C34 -> 0.05
A35: Labour | B35: 20 | C35: 15 | D35: =C35/B35 -> 0.75
B37: =SUM(B30:B32) -> 16 | D37: =SUM(D30:D32) -> 85.252233
A39: COST | D39: =D37 -> 85.252233
A40: PER TWIN PACK | D40: =D39/8 -> 10.656529

Sheet Bacon Puff
A1: Grasmere Farm Manual
A2: Product Page
A3: Bacon & Cheese Puff
A4: INGREDIENTS | B4: . All allergens in BOLD.
A16: Product | B16: Raw Bacon & Cheese Puff | G16: Product | H16: Raw Bacon & Cheese Puff boxed
B17: Weight | C17: Cost | D17: Total | H17: Weight | I17: Cost | J17: Total
A18: Smoked Bacon | B18: 0.025 | C18: 2.9 | D18: =B18*C18 -> 0.0725 | G18: Puff | H18: 28 | I18: =D26 -> 0.44894 | J18: =H18*I18 -> 12.57032
A19: Cheese | B19: 0.018 | C19: ='Ingredient Cost'!D42 -> 0.17 | D19: =B19*C19 -> 0.00306 | G19: Case | H19: 1 | I19: ='Ingredient Cost'!D108 -> 0.2 | J19: =H19*I19 -> 0.2
A20: Tomato Pureee | B20: 0.01 | C20: ='Ingredient Cost'!D43 -> 0.31 | D20: =B20*C20 -> 0.0031 | G20: Cooking Paper | H20: 2 | I20: ='Ingredient Cost'!D86 -> 0.12 | J20: =H20*I20 -> 0.24
A21: Pasty | B21: 0.062 | C21: ='Ingredient Cost'!D9 -> 1.94 | D21: =B21*C21 -> 0.12028 | G21: Labour | I21: 15 | J21: =I21/H21 -> #DIV/0!
A22: Labour | B22: 60 | C22: 15 | D22: =C22/B22 -> 0.25
A26: COST | D26: =SUM(D18:D22) -> 0.44894 | G26: COST | J26: =SUM(J18:J20) -> 13.01032
G27: PER EACH | J27: =J26/48 -> 0.27104833
A28: Product | B28: Raw Large Bacon & Cheese Puff | G28: Product | H28: Raw Large Bacon & Cheese Puff boxed
B29: Weight | C29: Cost | D29: Total | H29: Weight | I29: Cost | J29: Total
A30: Smoked Bacon | B30: 0.032 | D30: =B30*C30 -> 0 | G30: Puff | H30: 28 | I30: =D37 -> 0.966 | J30: =H30*I30 -> 27.048
A31: Cheese | B31: 234 | D31: =B31*C31 -> 0 | G31: Case | H31: 1 | I31: ='Ingredient Cost'!D109 -> 0.27 | J31: =H31*I31 -> 0.27
A32: Tomato Pureee | B32: 0.013 | D32: =B32*C32 -> 0 | G32: Cooking Paper | H32: 2 | I32: ='Ingredient Cost'!D97 -> 0.2 | J32: =H32*I32 -> 0.4
A33: Pasty | B33: 0.08 | C33: ='Ingredient Cost'!D20 -> 8.95 | D33: =B33*C33 -> 0.716 | G33: Labour | I33: 15 | J33: =I33/H33 -> #DIV/0!
A34: Labour | B34: 60 | C34: 15 | D34: =C34/B34 -> 0.25
A37: COST | D37: =SUM(D30:D34) -> 0.966 | G37: COST | J37: =SUM(J30:J32) -> 27.718
G38: PER EACH | J38: =J37/48 -> 0.57745833

Sheet Chorizo Puff
A1: Grasmere Farm Manual
A2: Product Page
A3: Chorizo Puff
A4: INGREDIENTS | B4: . All allergens in BOLD.
A16: Product | B16: Raw Chorizo Puff | G16: Product | H16: Raw Chorizo & Cheese Puff boxed
B17: Weight | C17: Cost | D17: Total | H17: Weight | I17: Cost | J17: Total
A18: Chorizo | B18: 0.025 | C18: 6 | D18: =B18*C18 -> 0.15 | G18: Puff | H18: 28 | I18: =D26 -> 0.52028 | J18: =H18*I18 -> 14.56784
A19: Cheese | B19: 0.018 | D19: =B19*C19 -> 0 | G19: Case | H19: 1 | I19: ='Ingredient Cost'!D108 -> 0.2 | J19: =H19*I19 -> 0.2
A20: Tomato Pureee | B20: 0.01 | D20: =C20/B20 -> 0 | G20: Cooking Paper | H20: 2 | I20: ='Ingredient Cost'!D86 -> 0.12 | J20: =H20*I20 -> 0.24
A21: Pasty | B21: 0.062 | C21: ='Ingredient Cost'!D9 -> 1.94 | D21: =B21*C21 -> 0.12028 | G21: Labour | I21: 15 | J21: =I21/H21 -> #DIV/0!
A22: Labour | B22: 60 | C22: 15 | D22: =C22/B22 -> 0.25
A26: COST | D26: =SUM(D18:D22) -> 0.52028 | G26: COST | J26: =SUM(J18:J20) -> 15.00784
G27: PER EACH | J27: =J26/48 -> 0.31266333

Sheet Onion Puff
A1: Grasmere Farm Manual
A2: Product Page
A3: Chorizo Puff
A4: INGREDIENTS | B4: . All allergens in BOLD.
A16: Product | B16: Raw Chorizo Puff | G16: Product | H16: Raw Chorizo & Cheese Puff boxed
B17: Weight | C17: Cost | D17: Total | H17: Weight | I17: Cost | J17: Total
A18: Onion | B18: 0.025 | C18: ='Ingredient Cost'!D34 -> 5.27 | D18: =B18*C18 -> 0.13175 | G18: Puff | H18: 28 | I18: =D26 -> 0.50203 | J18: =H18*I18 -> 14.05684
A19: Cheese | B19: 0.018 | D19: =B19*C19 -> 0 | G19: Case | H19: 1 | I19: ='Ingredient Cost'!D108 -> 0.2 | J19: =H19*I19 -> 0.2
A20: Tomato Pureee | B20: 0.01 | D20: =C20/B20 -> 0 | G20: Cooking Paper | H20: 2 | I20: ='Ingredient Cost'!D86 -> 0.12 | J20: =H20*I20 -> 0.24
A21: Pasty | B21: 0.062 | C21: ='Ingredient Cost'!D9 -> 1.94 | D21: =B21*C21 -> 0.12028 | G21: Labour | I21: 15 | J21: =I21/H21 -> #DIV/0!
A22: Labour | B22: 60 | C22: 15 | D22: =C22/B22 -> 0.25
A26: COST | D26: =SUM(D18:D22) -> 0.50203 | G26: COST | J26: =SUM(J18:J20) -> 14.49684
G27: PER EACH | J27: =J26/48 -> 0.3020175

Sheet Pork Pie v2
A1: Grasmere Farm
A2: Product Costings
A3: Pork Pie
A4: INGREDIENTS | B4: . All allergens in BOLD.
A16: Sub-recipes
A18: Seasoning | F18: Pork Pie Meat | K18: Hot Water Pastry | P18: Pork Pie Meat from Butchery
B19: Weight | C19: Cost | D19: Total | G19: Weight | H19: Cost | I19: Total | L19: Weight | M19: Cost | N19: Total | Q19: Cost | R19: Units per tray | S19: Cost per unit
A20: Salt | B20: 5 | C20: ='Ingredient Cost'!$D$8 -> 0.54 | D20: =B20*C20 -> 2.7 | F20: Pork Pie Meat | G20: 14.25 | H20: ='Ingredient Cost'!$D$47 -> 21.25 | I20: =G20*H20 -> 302.8125 | K20: Water | L20: 2.5 | P20: Mini | Q20: 52.5 | R20: 259 | S20: =Q20/R20 -> 0.2027027
A21: White Pepper | B21: 1.7 | C21: ='Ingredient Cost'!$D$10 -> 11 | D21: =B21*C21 -> 18.7 | F21: Seasoning | G21: 0.4 | H21: =$D$25 -> 43.987 | I21: =G21*H21 -> 17.5948 | K21: Fat/Butter | L21: 4 | M21: ='Ingredient Cost'!$D$6 -> 2.06 | N21: =L21*M21 -> 8.24 | P21: Small | Q21: 52.5 | R21: 101 | S21: =Q21/R21 -> 0.51980198
A22: Jelly | B22: 1.1 | C22: ='Ingredient Cost'!$D$79 -> 17.85 | D22: =B22*C22 -> 19.635 | K22: Flour | L22: 8 | M22: ='Ingredient Cost'!$D$7 -> 0.62 | N22: =L22*M22 -> 4.96 | P22: Med | Q22: 52.5 | R22: 50 | S22: =Q22/R22 -> 1.05
A23: Maize | B23: 0.08 | C23: ='Ingredient Cost'!$D$25 -> 36.9 | D23: =B23*C23 -> 2.952 | K23: Salt | L23: 0.15 | M23: ='Ingredient Cost'!$D$8 -> 0.54 | N23: =L23*M23 -> 0.081
A24: Mustard | B24: 0.08 | C24: ='Ingredient Cost'!$D$23 -> 9.37 | D24: =B24*C24 -> 0.7496
A25: Total Weight | B25: =SUM(B20:B24) -> 7.96 | D25: =SUM(D20:D23) -> 43.987 | F25: Total Weight | G25: =SUM(G20:G24) -> 14.65 | I25: =SUM(I20:I23) -> 320.4073 | K25: Total Weight | L25: =L20+L21+L22+L23 -> 14.65 | N25: =SUM(N20:N23) -> 13.281
A27: COST | D27: =D25/B25 -> 5.526005 | F27: COST | I27: =I25/G25 -> 21.870805 | K27: COST | N27: =N25/L25 -> 0.9065529
A29: COGS
A31: Mini | F31: Small | K31: Medium
B32: Weight | C32: Cost | D32: Total | G32: Weight | H32: Cost | I32: Total | L32: Weight | M32: Cost | N32: Total
A33: Pastry Base | C33: ='Pastry Costing'!$C$23 -> 0.058925939 | D33: =C33 -> 0.058925939 | F33: Pastry Base | H33: ='Pastry Costing'!$C$24 -> 0.10878635 | I33: =H33 -> 0.10878635 | K33: Pastry Base | M33: ='Pastry Costing'!$C$25 -> 0.19037611 | N33: =M33 -> 0.19037611
A34: Pork Meat | D34: =S20 -> 0.2027027 | F34: Pork Meat | I34: =S21 -> 0.51980198 | K34: Pork Meat | N34: =S22 -> 1.05
A35: Jelly | B35: 0.01 | C35: ='Ingredient Cost'!$D$79 -> 17.85 | D35: =B35*C35 -> 0.1785 | F35: Jelly | G35: 0.02 | H35: 0 | I35: =G35*H35 -> 0 | K35: Jelly | L35: 0.03 | M35: ='Ingredient Cost'!$D$79 -> 17.85 | N35: =L35*M35 -> 0.5355
A36: Pastry Lid | C36: ='Pastry Costing'!$E$23 -> 0.018131058 | D36: =C36 -> 0.018131058 | F36: Pastry Lid | H36: ='Pastry Costing'!$E$24 -> 0.036262116 | I36: =H36 -> 0.036262116 | K36: Pastry Lid | M36: ='Pastry Costing'!$E$25 -> 0.054393174 | N36: =M36 -> 0.054393174
A37: Foil | C37: ='Ingredient Cost'!$D$98 -> 0.02 | D37: =C37 -> 0.02 | F37: Foil | H37: ='Ingredient Cost'!$D$99 -> 0.07 | I37: =H37 -> 0.07 | K37: Foil | M37: ='Ingredient Cost'!$D$100 -> 0.08 | N37: =M37 -> 0.08
A38: Labour | B38: 240 | C38: 20 | D38: =C38/B38 -> 0.083333333 | F38: Labour | G38: 240 | H38: 20 | I38: =H38/G38 -> 0.083333333 | K38: Labour | L38: 200 | M38: 20 | N38: =M38/L38 -> 0.1
A39: Packaging | B39: 1 | C39: 0.01 | D39: =C39/B39 -> 0.01 | F39: Packaging | G39: 1 | H39: 0.01 | I39: =H39/G39 -> 0.01 | K39: Packaging | L39: 1 | M39: 0.01 | N39: =M39/L39 -> 0.01
A40: Labour (packing) | B40: 240 | C40: 20 | D40: =C40/B40 -> 0.083333333 | F40: Labour (packing) | G40: 240 | H40: 20 | I40: =H40/G40 -> 0.083333333 | K40: Labour (packing) | L40: 240 | M40: 20 | N40: =M40/L40 -> 0.083333333
A42: COST | D42: =SUM(D33:D40) -> 0.65492637 | F42: COST | I42: =SUM(I33:I41) -> 0.91151711 | K42: COST | N42: =SUM(N33:N40) -> 2.1036026
A44: 2LB | F44: 3LB
B45: Weight | C45: Cost | D45: Total | G45: Weight | H45: Cost | I45: Total
A46: Pastry Base | C46: ='Pastry Costing'!$C$26 -> 0.40341604 | D46: =C46 -> 0.40341604 | F46: Pastry Base | H46: ='Pastry Costing'!$C$27 -> 0.40341604 | I46: =H46 -> 0.40341604
A47: Pork Meat | B47: 0.1 | C47: 52.5 | D47: =B47*C47 -> 5.25 | F47: Pork Meat | G47: 0.2 | H47: 52.5 | I47: =G47*H47 -> 10.5
A48: Jelly | B48: 0.05 | C48: ='Ingredient Cost'!$D$79 -> 17.85 | D48: =B48*C48 -> 0.8925 | F48: Jelly | G48: 0.05 | H48: ='Ingredient Cost'!$D$79 -> 17.85 | I48: =G48*H48 -> 0.8925
A49: Pastry Lid | C49: ='Pastry Costing'!$E$26 -> 0.054393174 | D49: =C49 -> 0.054393174 | F49: Pastry Lid | H49: ='Pastry Costing'!$E$27 -> 0.14958123 | I49: =H49 -> 0.14958123
A50: Labour | B50: 16 | C50: 20 | D50: =C50/B50 -> 1.25 | F50: Labour | G50: 10 | H50: 20 | I50: =H50/G50 -> 2
A51: Foil | C51: ='Ingredient Cost'!$D$100 -> 0.08 | D51: =C51 -> 0.08 | F51: Foil | H51: ='Ingredient Cost'!$D$100 -> 0.08 | I51: =H51 -> 0.08
A52: Packaging | B52: 1 | C52: 0.01 | D52: =C52/B52 -> 0.01 | F52: Packaging | G52: 1 | H52: 0.01 | I52: =H52/G52 -> 0.01
A53: Labour (packing) | B53: 240 | C53: 20 | D53: =C53/B53 -> 0.083333333 | F53: Labour (packing) | G53: 240 | H53: 20 | I53: =H53/G53 -> 0.083333333
A55: COST | D55: =SUM(D46:D53) -> 8.0236425 | F55: COST | I55: =SUM(I46:I54) -> 14.118831
A58: CASES
A60: Mini pack of 2 | F60: Mini pack of 6
B61: Weight | C61: Cost | D61: Total | G61: Weight | H61: Cost | I61: Total
...

Sheet 1lb Pork Pie
A1: Grasmere Farm Manual
A2: Product Page
A3: Pork Pies
A4: INGREDIENTS | B4: . All allergens in BOLD.
A16: Product | B16: Pork Pie Seasoning | F16: Product | G16: Pork Pie Meat Mix | K16: Product | L16: Pork Pie Meat & Stilton Mix | U16: 240
B17: Weight | C17: Cost | D17: Total | G17: Weight | H17: Cost | I17: Total | L17: Weight | M17: Cost | N17: Total | U17: 480
A18: Salt | B18: 5 | C18: ='Ingredient Cost'!$D$8 -> 0.54 | D18: =B18*C18 -> 2.7 | F18: Pork Pie Meat | G18: 14.25 | H18: ='Ingredient Cost'!$D$47 -> 21.25 | I18: =G18*H18 -> 302.8125 | K18: Pork Pie Meat | L18: 14.25 | M18: ='Ingredient Cost'!$D$47 -> 21.25 | N18: =L18*M18 -> 302.8125 | U18: 240
A19: White Pepper | B19: 1.7 | C19: ='Ingredient Cost'!$D$10 -> 11 | D19: =B19*C19 -> 18.7 | F19: Seasoning | G19: 0.4 | H19: =$D$25 -> 5.526005 | I19: =G19*H19 -> 2.210402 | K19: Seasoning | L19: 0.4 | M19: =$I$25 -> 20.820676 | N19: =L19*M19 -> 8.3282704 | U19: 200
A20: Jelly | B20: 1.1 | C20: ='Ingredient Cost'!$D$79 -> 17.85 | D20: =B20*C20 -> 19.635 | K20: Stilton | L20: 1.1 | M20: ='Ingredient Cost'!$D$18 -> 4.75 | N20: =L20*M20 -> 5.225 | U20: 12
A21: Maize | B21: 0.08 | C21: ='Ingredient Cost'!$D$25 -> 36.9 | D21: =B21*C21 -> 2.952 | U21: 10
A22: Mustard | B22: 0.08 | C22: ='Ingredient Cost'!$D$23 -> 9.37 | D22: =B22*C22 -> 0.7496
B23: =SUM(B18:B22) -> 7.96 | D23: =SUM(D18:D21) -> 43.987 | G23: =SUM(G18:G22) -> 14.65 | I23: =SUM(I18:I21) -> 305.0229 | L23: =SUM(L18:L22) -> 15.75 | N23: =SUM(N18:N21) -> 316.36577
A25: COST | D25: =D23/B23 -> 5.526005 | F25: COST | I25: =I23/G23 -> 20.820676 | K25: COST | N25: =N23/L23 -> 20.086716
A27: Product | B27: Mini Pork Pie Stilton | F27: Product | G27: Mini Pork Pie lided | K27: Product | L27: Small | P27: Product | Q27: Small with Stilton | U27: Product | V27: Medium | Z27: Product | AA27: Medium lided with Stilton | AE27: Product | AF27: 2lb | AJ27: Product | AK27: 3lb
B28: Weight | C28: Cost | D28: Total | G28: Weight | H28: Cost | I28: Total | L28: Weight | M28: Cost | N28: Total | Q28: Weight | R28: Cost | S28: Total | V28: Weight | W28: Cost | X28: Total | AA28: Weight | AB28: Cost | AC28: Total | AF28: Weight | AG28: Cost | AH28: Total | AK28: Weight | AL28: Cost | AM28: Total
A29: Pastry Base | C29: ='Pastry Costing'!$C$23 -> 0.058925939 | D29: =C29 -> 0.058925939 | F29: Pastry Base | H29: ='Pastry Costing'!$C$23 -> 0.058925939 | I29: =H29 -> 0.058925939 | K29: Pastry Base | M29: ='Pastry Costing'!$C$24 -> 0.10878635 | N29: =M29 -> 0.10878635 | P29: Pastry Base | R29: ='Pastry Costing'!$C$24 -> 0.10878635 | S29: =R29 -> 0.10878635 | U29: Pastry Base | W29: ='Pastry Costing'!$C$25 -> 0.19037611 | X29: =W29 -> 0.19037611 | Z29: Pastry Base | AB29: ='Pastry Costing'!C25 -> 0.19037611 | AC29: =AB29 -> 0.19037611 | AE29: Pastry Base | AG29: ='Pastry Costing'!$C$26 -> 0.40341604 | AH29: =AG29 -> 0.40341604 | AJ29: Pastry Base | AL29: ='Pastry Costing'!$C$27 -> 0.40341604 | AM29: =AL29 -> 0.40341604
